Workbook

Sheet RESUMEN_EJECUTIVO
A1: GOBIERNO AUTÓNOMO MUNICIPAL DE SUCRE & ECOTRAFFIC — MODELO TARIFARIO AUDITADO v3.2
A2: Bases Técnicas y Materiales de Negociación | Costos de Operación Vehicular, Economía del Hogar y Tarifas Sociales
A4: ESCENARIO: Base Observada (987 unidades) | D4: MODO: Producción Auditada (82.475 km/día - Factor: 1,0050) | H4: AUDITORÍA: Mantenimiento v2 y Rendimiento Diésel CERRADOS
A6: TARIFA ADULTO VIGENTE | C6: TARIFA ADULTO TÉCNICA | E6: TARIFA ADULTO SOCIAL | G6: INGRESO HOGAR (TÉCNICA) | I6: INGRESO HOGAR (SOCIAL) | K6: MANTENIMIENTO AUDITADO
A7: =TARIFAS_CATEGORIA!D5 -> 4.5 | C7: =TARIFAS_CATEGORIA!E5 -> 3.4430825 | E7: =TARIFAS_CATEGORIA!F5 -> 3.5 | G7: =ECONOMIA_PROPIETARIO!C22 -> 5393.3 | I7: =ECONOMIA_PROPIETARIO!D22 -> 6220.3455 | K7: =MANTENIMIENTO_NISSAN!J55 -> 2840.1667
A8: Ponderada: Bs. 3,50 / viaje | C8: Equilibrio financiero: Bs. 2,69 | E8: Propuesta mesa: Bs. 2,80 | G8: Salario + Retorno capital | I8: Salario + Caja libre mensual | K8: Planilla v2 rebajada por unidad
A10: DIAGNÓSTICO TÉCNICO PARA LA MESA: Con el mantenimiento auditado v2 (Bs. 2.869,75/mes), el Costo Regulatorio baja a Bs. 18.790,59/mes. La Tarifa Técnica de Adulto desciende a Bs. 3,45. La tarifa vigente de Bs. 4,50 genera una sobreganancia de Bs. 5.729,47/mes por microbús. La propuesta social de Bs. 3,80 cubre el 100% de costos y deja un ingreso mensual familiar de Bs. 7.408,02.
A12: TARIFAS POR CATEGORÍA SOCIAL — NEGOCIACIÓN | G12: HOJA DE COSTOS POR UNIDAD / MES (COV AUDITADO)
A13: Categoría Social | B13: % Demanda | C13: Vigente (Bs) | D13: Técnica Equiv. (Bs) | E13: Social Propuesta (Bs) | G13: Componente del Costo | H13: Bs / Mes | I13: % OPEX | J13: Tratamiento Técnico | K13: Estado Auditoría
A14: =TARIFAS_CATEGORIA!A5 -> Adultos | B14: =TARIFAS_CATEGORIA!B5 -> 0.58 | C14: =TARIFAS_CATEGORIA!D5 -> 4.5 | D14: =TARIFAS_CATEGORIA!E5 -> 3.4430825 | E14: =TARIFAS_CATEGORIA!F5 -> 3.5 | G14: Combustible (Diésel) | H14: =COSTOS_OPERACION_COV!E6 -> 8154.1392 | I14: =H14/$H$20 -> 0.43463192 | J14: Variable por km recorrido | K14: CERRADO
A15: =TARIFAS_CATEGORIA!A6 -> Adultos mayores | B15: =TARIFAS_CATEGORIA!B6 -> 0.07 | C15: =TARIFAS_CATEGORIA!D6 -> 3.5 | D15: =TARIFAS_CATEGORIA!E6 -> 2.677953 | E15: =TARIFAS_CATEGORIA!F6 -> 3 | G15: Mantenimiento variable por km | H15: =COSTOS_OPERACION_COV!E7 -> 713.94312 | I15: =H15/$H$20 -> 0.038054595 | J15: Variable por km recorrido | K15: CERRADO
A16: =TARIFAS_CATEGORIA!A7 -> Universitarios | B16: =TARIFAS_CATEGORIA!B7 -> 0.18 | C16: =TARIFAS_CATEGORIA!D7 -> 2.5 | D16: =TARIFAS_CATEGORIA!E7 -> 1.9128236 | E16: =TARIFAS_CATEGORIA!F7 -> 2 | G16: Mantenimiento fijo en el tiempo | H16: =COSTOS_OPERACION_COV!E11 -> 2126.2235 | I16: =H16/$H$20 -> 0.11333196 | J16: Fijo mensual por microbús | K16: CERRADO
A17: =TARIFAS_CATEGORIA!A8 -> Colegiales | B17: =TARIFAS_CATEGORIA!B8 -> 0.1 | C17: =TARIFAS_CATEGORIA!D8 -> 1.5 | D17: =TARIFAS_CATEGORIA!E8 -> 1.1476942 | E17: =TARIFAS_CATEGORIA!F8 -> 1.5 | G17: Personal (Conductor + Aguinaldo) | H17: =COSTOS_OPERACION_COV!E12+COSTOS_OPERACION_COV!E13 -> 3575 | I17: =H17/$H$20 -> 0.19055465 | J17: Fijo mensual por microbús | K17: CERRADO
A18: =TARIFAS_CATEGORIA!A9 -> Escolares | B18: =TARIFAS_CATEGORIA!B9 -> 0.05 | C18: =TARIFAS_CATEGORIA!D9 -> 1 | D18: =TARIFAS_CATEGORIA!E9 -> 0.76512944 | E18: =TARIFAS_CATEGORIA!F9 -> 1 | G18: Otros Costos Fijos Administrativos | H18: =SUM(COSTOS_OPERACION_COV!E14:E20) -> 720.41667 | I18: =H18/$H$20 -> 0.038399648 | J18: Fijo mensual por microbús | K18: CERRADO
A19: =TARIFAS_CATEGORIA!A10 -> Discapacidad / menores de 5 | B19: =TARIFAS_CATEGORIA!B10 -> 0.02 | C19: =TARIFAS_CATEGORIA!D10 -> 0 | D19: =TARIFAS_CATEGORIA!E10 -> 0 | E19: =TARIFAS_CATEGORIA!F10 -> 0 | G19: Costos de Capital (Depreciación + WACC) | H19: =COSTOS_OPERACION_COV!E28 -> 3471.3 | I19: =H19/$H$20 -> 0.18502723 | J19: Costo de capital regulatorio | K19: CERRADO
A20: PROMEDIO PONDERADO: | B20: =TARIFAS_CATEGORIA!B11 -> 1 | C20: =TARIFAS_CATEGORIA!D11 -> 3.505 | D20: =TARIFAS_CATEGORIA!E11 -> 2.6817787 | E20: =TARIFAS_CATEGORIA!F11 -> 2.8 | G20: COSTO REGULATORIO TOTAL: | H20: =COSTOS_OPERACION_COV!E30 -> 18761.023 | I20: 100.0% | J20: Costo integral de red | K20: AUDITADO
A22: ECONOMÍA MENSUAL DEL PROPIETARIO — UNIDAD / MES | G22: OPERACIÓN, PRODUCTIVIDAD Y CONCILIACIÓN DE RED
A23: Concepto Financiero | B23: Tarifa Vigente (Bs) | C23: Tarifa Técnica (Bs) | D23: Tarifa Social (Bs) | E23: Lectura Económica | G23: Indicador Operativo | H23: Valor Activo | I23: Unidad | J23: Semáforo | K23: Definición Metodológica
A24: Recaudación neta mensual | B24: =ECONOMIA_PROPIETARIO!B8 -> 24520.064 | C24: =ECONOMIA_PROPIETARIO!C8 -> 18761.023 | D24: =ECONOMIA_PROPIETARIO!D8 -> 19588.068 | E24: Ingreso efectivo por pasajes | G24: Vueltas medias por día | H24: =SUPUESTOS_PARAMETROS!B15 -> 3 | I24: vueltas/día | J24: Informativo | K24: Ciclos completos ida y vuelta declarados
A25: OPEX en efectivo | B25: =ECONOMIA_PROPIETARIO!B13 -> 15289.723 | C25: =ECONOMIA_PROPIETARIO!C13 -> 15289.723 | D25: =ECONOMIA_PROPIETARIO!D13 -> 15289.723 | E25: Salidas inmediatas de operación | G25: km implícitos de las 32 rutas | H25: =RENTABILIDAD_32_RUTAS!E4 -> 82066.487 | I25: km/día | J25: Conciliación | K25: Distancia de ciclo x flota x vueltas
A26: Reserva para reposición (Deprec.) | B26: =ECONOMIA_PROPIETARIO!B17 -> 1653 | C26: =ECONOMIA_PROPIETARIO!C17 -> 1653 | D26: =ECONOMIA_PROPIETARIO!D17 -> 1653 | E26: Ahorro para cambiar el vehículo | G26: km auditados de red (GPS) | H26: =SUPUESTOS_PARAMETROS!B12 -> 82475 | I26: km/día | J26: Auditado | K26: Producción física satelital independiente
A27: Retorno normal al capital (11%) | B27: =ECONOMIA_PROPIETARIO!B19 -> 1818.3 | C27: =ECONOMIA_PROPIETARIO!C19 -> 1818.3 | D27: =ECONOMIA_PROPIETARIO!D19 -> 1818.3 | E27: Remuneración justa a la inversión | G27: Factor de Conciliación de red | H27: =RENTABILIDAD_32_RUTAS!K4 -> 1.0049778 | I27: factor | J27: ÓPTIMO | K27: Auditado dividido entre implícito (1,0050)
A28: Utilidad económica excedente | B28: =ECONOMIA_PROPIETARIO!B20 -> 5759.0412 | C28: =ECONOMIA_PROPIETARIO!C20 -> 0 | D28: =ECONOMIA_PROPIETARIO!D20 -> 827.04551 | E28: Sobreganancia sobre retorno normal | G28: Brecha de producción antes de ajuste | H28: =RENTABILIDAD_32_RUTAS!K4-1 -> 0.0049778357 | I28: % brecha | J28: ÓPTIMO | K28: Diferencia de oferta absorbida (0,50%)
A29: Remuneración por conducir (Chofer) | B29: =ECONOMIA_PROPIETARIO!B21 -> 3575 | C29: =ECONOMIA_PROPIETARIO!C21 -> 3575 | D29: =ECONOMIA_PROPIETARIO!D21 -> 3575 | E29: Sueldo y aguinaldo por trabajo | G29: Índice de Pasajeros por Km (IPK) | H29: =SUPUESTOS_PARAMETROS!B20 -> 3.2199939 | I29: pax/km | J29: Auditado | K29: Demanda total dividida entre producción km
A30: INGRESO TOTAL DEL HOGAR | B30: =ECONOMIA_PROPIETARIO!B22 -> 11152.341 | C30: =ECONOMIA_PROPIETARIO!C22 -> 5393.3 | D30: =ECONOMIA_PROPIETARIO!D22 -> 6220.3455 | E30: Total de caja familiar mensual | G30: Rutas con déficit (Tarifa Vigente) | H30: 1 | I30: rutas / 32 | J30: Leve | K30: Sólo Línea 12 amarillo (tramo corto)
G31: Rutas con déficit (Tarifa Social) | H31: 7 | I31: rutas / 32 | J31: Negociar | K31: Demanda imputada con IPK promedio sistema

Sheet MANTENIMIENTO_NISSAN
A1: GOBIERNO AUTÓNOMO MUNICIPAL DE SUCRE & ECOTRAFFIC — PLANILLA TÉCNICA DE MANTENIMIENTO
A2: Costo de Mantenimiento y Repuestos Auditado (Versión Rebajada Oficial v2) | Microbús Nissan Civilian 1990–1998
A4: N° | B4: Sistemas del Vehículo / Componente | C4: Condición | D4: Costo Insumos (Bs) | E4: Cantidad | F4: Unidad | G4: Costo Mano de Obra (Bs) | H4: Costo Total (Bs) | I4: Periodicidad (Años) | J4: Costo Anual (Bs) | K4: Observaciones Técnicas | L4: Intervalo Fabricante (Km)
A5: 1 | B5: Correas de motor | C5: C | D5: 100 | E5: 2 | F5: pzas | G5: 60 | H5: =D5*E5+G5 -> 260 | I5: 1 | J5: =H5/I5 -> 260 | K5: Mediante verificacion visual y km recorrido o cada 3 años | L5: 40000
A6: 2 | B6: Aceite de motor 15w40 | C6: C | D6: 40 | E6: 12 | F6: L | G6: 0 | H6: =D6*E6+G6 -> 480 | I6: 0.08 | J6: =H6/I6 -> 6000 | K6: M.O. incluido | L6: 5000
A7: 3 | B7: Filtro de aceite | C7: C | D7: 50 | E7: 2 | F7: pzas | G7: 0 | H7: =D7*E7+G7 -> 100 | I7: 0.08 | J7: =H7/I7 -> 1250 | K7: M.O. incluido | L7: 5000
A8: 4 | B8: Ventilador | C8: C | D8: 220 | E8: 1 | F8: pza | G8: 40 | H8: =D8+G8 -> 260 | I8: 2 | J8: =H8/I8 -> 130 | K8: Mediante inspecciones tecnicas periodicas | L8: 60000
A9: 5 | B9: Anticongelante | C9: C | D9: 50 | E9: 6 | F9: L | G9: 0 | H9: =D9*E9+G9 -> 300 | I9: 1 | J9: =H9/I9 -> 300 | K9: M.O. incluido | L9: 40000
A10: 6 | B10: Termostato | C10: C | D10: 200 | E10: 1 | F10: pza | G10: 100 | H10: =D10+G10 -> 300 | I10: 2 | J10: =H10/I10 -> 150 | L10: 80000
A11: 7 | B11: Filtro de combustible | C11: C | D11: 80 | E11: 1 | F11: pza | G11: 0 | H11: =D11+G11 -> 80 | I11: 0.08 | J11: =H11/I11 -> 1000 | K11: M.O. incluido | L11: 5000
A12: 8 | B12: Filtro de aire | C12: C | D12: 210 | E12: 1 | F12: pza | G12: 0 | H12: =D12+G12 -> 210 | I12: 0.5 | J12: =H12/I12 -> 420 | K12: M.O. incluido | L12: 12000
A13: 9 | B13: Reparación Kit completo motor | C13: C | D13: 7000 | E13: 1 | F13: Kit | G13: 3500 | H13: =D13+G13 -> 10500 | I13: 4 | J13: =H13/I13 -> 2625 | K13: Reparación general de bloque y componentes | L13: 200000
A14: 10 | B14: Afinado de motor | C14: MP | D14: 230 | E14: 1 | F14: pza | G14: 230 | H14: =D14+G14 -> 460 | I14: 0.25 | J14: =H14/I14 -> 1840 | L14: 25000
A15: 11 | B15: Disco de embrague | C15: C | D15: 550 | E15: 1 | F15: kit | G15: 600 | H15: =D15+G15 -> 1150 | I15: 1 | J15: =H15/I15 -> 1150 | L15: 60000
A16: 12 | B16: Rectificado Prensa | C16: C | D16: 250 | E16: 1 | F16: kit | G16: 0 | H16: =D16+G16 -> 250 | I16: 2 | J16: =H16/I16 -> 125 | L16: 40000
A17: 13 | B17: Volante de inercia | C17: C | D17: 250 | E17: 1 | F17: kit | G17: 0 | H17: =D17+G17 -> 250 | I17: 2 | J17: =H17/I17 -> 125 | L17: 40000
A18: 14 | B18: Rodamiento desplazador | C18: C | D18: 350 | E18: 1 | F18: kit | G18: 0 | H18: =D18+G18 -> 350 | I18: 2 | J18: =H18/I18 -> 175 | L18: 40000
A19: 15 | B19: Cubetas de cilindros de embrague | C19: C | D19: 60 | E19: 2 | F19: kit | G19: 0 | H19: =D19+G19 -> 60 | I19: 1 | J19: =H19/I19 -> 60 | L19: 10000
A20: 16 | B20: Aceite para transmisión | C20: C | D20: 80 | E20: 6 | F20: Lt | G20: 0 | H20: =D20*E20+G20 -> 480 | I20: 2 | J20: =H20/I20 -> 240 | K20: M.O. incluido | L20: 50000
A21: 18 | B21: Aceite de corona | C21: C | D21: 80 | E21: 6 | F21: Lt | G21: 0 | H21: =D21*E21+G21 -> 480 | I21: 2 | J21: =H21/I21 -> 240 | K21: M.O. incluido | L21: 50000
A22: 19 | B22: Crucetas de cardan | C22: C | D22: 200 | E22: 2 | F22: pza | G22: 150 | H22: =D22+G22 -> 350 | I22: 1 | J22: =H22/I22 -> 350 | L22: 30000
A23: 20 | B23: Corona | C23: C | D23: 5500 | E23: 1 | F23: pzas | G23: 420 | H23: =D23+G23 -> 5920 | I23: 5 | J23: =H23/I23 -> 1184 | L23: 150000
A24: 21 | B24: Eje motriz (par cónico diferencial) | C24: C | D24: 1000 | E24: 1 | F24: pzas | G24: 0 | H24: =D24+G24 -> 1000 | I24: 5 | J24: =H24/I24 -> 200 | L24: 150000
A25: 22 | B25: Conjunto pasadores/rodamientos punta eje | C25: C | D25: 400 | E25: 1 | F25: Juego | G25: 350 | H25: =D25+G25 -> 750 | I25: 2 | J25: =H25/I25 -> 375 | L25: 100000
A26: 25 | B26: Muñones de suspensión | C26: C | D26: 340 | E26: 4 | F26: pzas | G26: 160 | H26: =D26*E26+G26 -> 1520 | I26: 1 | J26: =H26/I26 -> 1520 | L26: 65000
A27: 26 | B27: Amortiguadores delanteros | C27: C | D27: 280 | E27: 2 | F27: pzas | G27: 110 | H27: =D27*E27+G27 -> 670 | I27: 2 | J27: =H27/I27 -> 335 | L27: 25000
A28: 27 | B28: Bujes de suspensión | C28: C | D28: 70 | E28: 8 | F28: pzas | G28: 150 | H28: =D28*E28+G28 -> 710 | I28: 2 | J28: =H28/I28 -> 355 | L28: 20000
A29: 28 | B29: Muelles posteriores | C29: C | D29: 300 | E29: 2 | F29: pzas | G29: 130 | H29: =D29*E29+G29 -> 730 | I29: 1 | J29: =H29/I29 -> 730 | L29: 100000
A30: 29 | B30: Perno Central de elásticos | C30: C | D30: 40 | E30: 2 | F30: pzas | G30: 130 | H30: =D30*E30+G30 -> 210 | I30: 1 | J30: =H30/I30 -> 210 | K30: M.O. incluido | L30: 50000
A31: 30 | B31: Amortiguadores posteriores | C31: C | D31: 250 | E31: 2 | F31: pzas | G31: 50 | H31: =D31*E31+G31 -> 550 | I31: 2 | J31: =H31/I31 -> 275 | L31: 25000
A32: 31 | B32: Bujes de barra estabilizadora | C32: C | D32: 60 | E32: 4 | F32: pzas | G32: 40 | H32: =D32*E32+G32 -> 280 | I32: 2 | J32: =H32/I32 -> 140 | L32: 65000
A33: 32 | B33: Bomba hidráulica de dirección | C33: C | D33: 1500 | E33: 1 | F33: pza | G33: 150 | H33: =D33+G33 -> 1650 | I33: 4 | J33: =H33/I33 -> 412.5 | L33: 100000
A34: 33 | B34: Caja de Dirección y retenes | C34: R | D34: 800 | E34: 1 | F34: pza | G34: 150 | H34: =D34+G34 -> 950 | I34: 4 | J34: =H34/I34 -> 237.5 | L34: 100000
A35: 34 | B35: Muñones de dirección | C35: C | D35: 250 | E35: 4 | F35: pzas | G35: 100 | H35: =D35*E35+G35 -> 1100 | I35: 1 | J35: =H35/I35 -> 1100 | L35: 65000
A36: 35 | B36: Líquido hidráulico | C36: C | D36: 30 | E36: 2 | F36: Lt | G36: 0 | H36: =D36*E36+G36 -> 60 | I36: 3 | J36: =H36/I36 -> 20 | K36: M.O. incluido | L36: 20000
A37: 36 | B37: Neumáticos, cámara y ponchillos (juego 6) | C37: C | D37: 1500 | E37: 6 | F37: pzas | G37: 150 | H37: =D37*E37+G37 -> 9150 | I37: 2 | J37: =H37/I37 -> 4575 | L37: 20000
A38: 37 | B38: Tambores traseros de freno | C38: C | D38: 800 | E38: 2 | F38: pzas | G38: 140 | H38: =D38*E38+G38 -> 1740 | I38: 5 | J38: =H38/I38 -> 348 | L38: 120000
A39: 38 | B39: Cilindro Maestro de freno | C39: C | D39: 500 | E39: 1 | F39: pza | G39: 80 | H39: =D39+G39 -> 580 | I39: 4 | J39: =H39/I39 -> 145 | L39: 100000
A40: 39 | B40: Cubetas de cilindro maestro | C40: C | D40: 150 | E40: 2 | F40: pzas | G40: 80 | H40: =D40*E40+G40 -> 380 | I40: 1 | J40: =H40/I40 -> 380 | L40: 50000
A41: 40 | B41: Cilindro auxiliar de freno | C41: C | D41: 30 | E41: 2 | F41: pzas | G41: 80 | H41: =D41*E41+G41 -> 140 | I41: 2 | J41: =H41/I41 -> 70 | L41: 100000
...

Sheet SUPUESTOS_PARAMETROS
A1: GOBIERNO AUTÓNOMO MUNICIPAL DE SUCRE & ECOTRAFFIC — PARÁMETROS OPERATIVOS Y ECONÓMICOS
A2: Variables del Sistema, Productividad de Red y Costos Unitarios | Versión Auditada Oficial v3.2
A4: 1. ESCENARIOS OPERATIVOS DE RED (REFERENCIA TÉCNICA)
A5: ID | B5: Escenario Operativo | C5: Flota Activa | D5: km Red / Día | E5: Pasajeros / Día | F5: Días / Mes | G5: Vueltas / Día | H5: Uso Metodológico
A6: 1 | B6: Base observada del estudio (Oficial) | C6: 987 | D6: 82475 | E6: 265569 | F6: 26 | G6: 3 | H6: Referencia primaria auditada para concertación
A7: 2 | B7: Calibración 32 rutas previa | C7: 874 | D7: 84782.635 | E7: 273000 | F7: 26 | G7: 3.5 | H7: Comparabilidad histórica con versión previa
A8: 3 | B8: Eficiencia operacional optimizada | C8: 800 | D8: 85317 | E8: 265569 | F8: 26 | G8: 3.85 | H8: Escenario de optimización y reorganización
A10: 2. PARÁMETROS ACTIVOS Y PRODUCTIVIDAD DEL SISTEMA (ESCENARIO 1 AUDITADO)
A11: Flota activa en operación | B11: =C6 -> 987 | C11: vehículos | D11: Padrón observado en servicio regular
A12: Producción de red auditada | B12: =D6 -> 82475 | C12: km/día | D12: Medición satelital GPS de campo consolidada
A13: Demanda diaria del sistema | B13: =E6 -> 265569 | C13: pasajeros/día | D13: Aforo integral de subidas/bajadas expandido
A14: Días de operación comercial al mes | B14: =F6 -> 26 | C14: días/mes | D14: Calendario de operación regular
A15: Vueltas medias por día por unidad | B15: =G6 -> 3 | C15: vueltas/día | D15: Ciclos completos ida y vuelta declarados
A16: Kilómetros recorridos por unidad/día | B16: =B12/B11 -> 83.561297 | C16: km/unidad/día | D16: Producción de red dividida entre flota activa
A17: Kilómetros recorridos por unidad/mes | B17: =B16*B14 -> 2172.5937 | C17: km/unidad/mes | D17: Kilometraje mensual para estructura de costos
A18: Pasajeros transportados por unidad/día | B18: =B13/B11 -> 269.06687 | C18: pax/unidad/día | D18: Demanda diaria dividida entre flota activa
A19: Pasajeros transportados por unidad/mes | B19: =B18*B14 -> 6995.7386 | C19: pax/unidad/mes | D19: Demanda mensual transportada por microbús
A20: Índice de Pasajeros por Kilómetro (IPK) | B20: =B13/B12 -> 3.2199939 | C20: pax/km | D20: Demanda total dividida entre producción de km
A22: 3. PARÁMETROS ECONÓMICOS DE LA UNIDAD (MICROBÚS TIPO NISSAN CIVILIAN)
A23: Propietario conduce unidad | B23: 1 | C23: 0=No, 1=Sí | D23: Condición representativa del parque automotor
A24: Puestos de conductor remunerados | B24: 1 | C24: conductores | D24: Régimen laboral estándar (1 turno de 3.300 Bs)
A25: Salario mensual conductor | B25: 3300 | C25: Bs/mes | D25: Convenio laboral / escala de remuneración
A26: Cargas sociales y provisiones | B26: 0.083333333 | C26: % salario | D26: Provisión de aguinaldo navideño (1/12)
A27: Rendimiento diésel base | B27: 5.5 | C27: km/litro | D27: Prueba de consumo en circuito urbano cerrado
A28: Factor de sobrecosto ralentí / congestión | B28: 0.15 | C28: % adicional | D28: Pérdida por tráfico y paradas continuas (15%)
A29: Precio oficial de diésel | B29: 17.95 | C29: Bs/litro | D29: Precio de mercado regulado vigente
A30: Mantenimiento total mensual auditado | B30: =MANTENIMIENTO_NISSAN!J55 -> 2840.1667 | C30: Bs/mes | D30: Planilla técnica v2 rebajada de repuestos y MO
A31: Proporción variable de mantenimiento | B31: 0.25137367 | C31: % variable | D31: Asignado a consumo por kilómetro recorrido
A32: Proporción fija de mantenimiento | B32: 0.74862633 | C32: % fijo | D32: Asignado a costos periódicos en el tiempo
A33: Valor de reposición del vehículo a nuevo | B33: 198360 | C33: Bs | D33: Cotización de microbús equivalente
A34: Valor residual al fin de vida útil | B34: 0 | C34: Bs | D34: Política regulatoria estándar (0%)
A35: Vida útil económica del microbús | B35: 120 | C35: meses | D35: 10 años de amortización regulatoria
A36: Tasa de retorno anual al capital invertido | B36: 0.11 | C36: % anual | D36: WACC / Costo de oportunidad del capital (11%)
A37: Umbral de revisión tarifaria trimestral | B37: 0.05 | C37: % variación | D37: Regla Laspeyres: gatillo de activación (5%)

Sheet COSTOS_OPERACION_COV
A1: GOBIERNO AUTÓNOMO MUNICIPAL DE SUCRE & ECOTRAFFIC — COSTOS DE OPERACIÓN VEHICULAR (COV)
A2: Estructura Desagregada de Costos Variables, Fijos y de Capital | Microbús Nissan Civilian Oficial v3.2
A4: A. COSTOS VARIABLES (DIRECTAMENTE DEPENDIENTES DEL KILOMETRAJE)
A5: Grupo | B5: Concepto de Costo | C5: Base de Cálculo | D5: Importe Base | E5: Costo Mensual (Bs) | F5: Costo / Km (Bs/km) | G5: % del Costo Total
A6: Combustible | B6: Diésel Oíl + sobrecosto congestión (15%) | C6: Rend. 5,50 km/l | 17,95 Bs/l | D6: =(SUPUESTOS_PARAMETROS!B17/SUPUESTOS_PARAMETROS!B27)*SUPUESTOS_PARAMETROS!B29*(1+SUPUESTOS_PARAMETROS!B28) -> 8154.1392 | E6: =D6 -> 8154.1392 | F6: =E6/SUPUESTOS_PARAMETROS!B17 -> 3.7531818 | G6: =E6/$E$32 -> 0.43463192
A7: Mantenimiento | B7: Mantenimiento dependiente de km (25,14%) | C7: Aceites, filtros, balatas, neumáticos | D7: =SUPUESTOS_PARAMETROS!B30*SUPUESTOS_PARAMETROS!B31 -> 713.94312 | E7: =D7 -> 713.94312 | F7: =E7/SUPUESTOS_PARAMETROS!B17 -> 0.32861327 | G7: =E7/$E$32 -> 0.038054595
A8: SUBTOTAL COSTOS VARIABLES (A): | E8: =SUM(E6:E7) -> 8868.0824 | F8: =E8/SUPUESTOS_PARAMETROS!B17 -> 4.0817951 | G8: =E8/$E$32 -> 0.47268651
A10: B. COSTOS FIJOS EN EFECTIVO (INDEPENDIENTES DEL KILOMETRAJE)
A11: Mantenimiento | B11: Mantenimiento periódico en el tiempo (74,86%) | C11: Reparaciones mecánicas y preventivas | D11: =SUPUESTOS_PARAMETROS!B30*SUPUESTOS_PARAMETROS!B32 -> 2126.2235 | E11: =D11 -> 2126.2235 | F11: =E11/SUPUESTOS_PARAMETROS!$B$17 -> 0.97865677 | G11: =E11/$E$32 -> 0.11333196
A12: Personal | B12: Remuneración de conductor profesional | C12: 1 chofer por unidad | D12: =SUPUESTOS_PARAMETROS!B25 -> 3300 | E12: =D12 -> 3300 | F12: =E12/SUPUESTOS_PARAMETROS!$B$17 -> 1.5189218 | G12: =E12/$E$32 -> 0.1758966
A13: Personal | B13: Cargas sociales y provisión de aguinaldo | C13: 8,33% sobre salario | D13: =E12*SUPUESTOS_PARAMETROS!B26 -> 275 | E13: =D13 -> 275 | F13: =E13/SUPUESTOS_PARAMETROS!$B$17 -> 0.12657682 | G13: =E13/$E$32 -> 0.01465805
A14: Administrativo | B14: Seguro Obligatorio de Accidentes (SOAT) | C14: Bs. 445 / 12 meses | D14: =445/12 -> 37.083333 | E14: =D14 -> 37.083333 | F14: =E14/SUPUESTOS_PARAMETROS!$B$17 -> 0.017068692 | G14: =E14/$E$32 -> 0.0019766158
A15: Administrativo | B15: Impuesto municipal a la propiedad vehicular | C15: Bs. 700 / 12 meses | D15: =700/12 -> 58.333333 | E15: =D15 -> 58.333333 | F15: =E15/SUPUESTOS_PARAMETROS!$B$17 -> 0.026849628 | G15: =E15/$E$32 -> 0.0031092833
A16: Administrativo | B16: Inspección Técnica Vehicular (ITV) | C16: Bs. 30 / 12 meses | D16: =30/12 -> 2.5 | E16: =D16 -> 2.5 | F16: =E16/SUPUESTOS_PARAMETROS!$B$17 -> 0.0011506983 | G16: =E16/$E$32 -> 0.000133255
A17: Administrativo | B17: Cuota sindical y gastos de administración | C17: Bs. 200 mensual por vehículo | D17: 200 | E17: =D17 -> 200 | F17: =E17/SUPUESTOS_PARAMETROS!$B$17 -> 0.092055868 | G17: =E17/$E$32 -> 0.0106604
A18: Administrativo | B18: Permiso de parada y rodaje diario | C18: Bs. 10 / día x 26 días | D18: =10*SUPUESTOS_PARAMETROS!B14 -> 260 | E18: =D18 -> 260 | F18: =E18/SUPUESTOS_PARAMETROS!$B$17 -> 0.11967263 | G18: =E18/$E$32 -> 0.01385852
A19: Administrativo | B19: Tarjeta de operación municipal | C19: Bs. 150 / 12 meses | D19: =150/12 -> 12.5 | E19: =D19 -> 12.5 | F19: =E19/SUPUESTOS_PARAMETROS!$B$17 -> 0.0057534917 | G19: =E19/$E$32 -> 0.00066627498
A20: Seguro | B20: Seguro de responsabilidad civil a terceros | C20: Póliza mensual comercial | D20: 150 | E20: =D20 -> 150 | F20: =E20/SUPUESTOS_PARAMETROS!$B$17 -> 0.069041901 | G20: =E20/$E$32 -> 0.0079952998
A21: SUBTOTAL COSTOS FIJOS EN EFECTIVO (B): | E21: =SUM(E11:E20) -> 6421.6402 | F21: =E21/SUPUESTOS_PARAMETROS!B17 -> 2.9557483 | G21: =E21/$E$32 -> 0.34228626
A23: TOTAL COSTO OPERATIVO EN EFECTIVO - OPEX (A + B): | E23: =E8+E21 -> 15289.723 | F23: =E23/SUPUESTOS_PARAMETROS!B17 -> 7.0375434 | G23: =E23/$E$32 -> 0.81497277
A25: C. COSTOS DE CAPITAL Y REGULATORIOS (AMORTIZACIÓN Y RETORNO DE INVERSIÓN)
A26: Capital | B26: Depreciación / Reserva reposición vehículo | C26: Vida útil 120 meses (10 años) | D26: =(SUPUESTOS_PARAMETROS!B33-SUPUESTOS_PARAMETROS!B34)/SUPUESTOS_PARAMETROS!B35 -> 1653 | E26: =D26 -> 1653 | F26: =E26/SUPUESTOS_PARAMETROS!$B$17 -> 0.76084175 | G26: =E26/$E$32 -> 0.088108204
A27: Capital | B27: Retorno permitido sobre capital invertido | C27: 11% anual sobre activo regulatorio | D27: =(SUPUESTOS_PARAMETROS!B33-SUPUESTOS_PARAMETROS!B34)*SUPUESTOS_PARAMETROS!B36/12 -> 1818.3 | E27: =D27 -> 1818.3 | F27: =E27/SUPUESTOS_PARAMETROS!$B$17 -> 0.83692592 | G27: =E27/$E$32 -> 0.096919024
A28: SUBTOTAL COSTOS DE CAPITAL (C): | E28: =SUM(E26:E27) -> 3471.3 | F28: =E28/SUPUESTOS_PARAMETROS!B17 -> 1.5977677 | G28: =E28/$E$32 -> 0.18502723
A30: COSTO ECONÓMICO REGULATORIO TOTAL POR UNIDAD (A + B + C): | E30: =E23+E28 -> 18761.023 | F30: =E30/SUPUESTOS_PARAMETROS!B17 -> 8.6353111 | G30: =1 -> 1
A32: Costo Regulatorio por Pasajero (Tarifa Técnica Ponderada): | E32: =E30 -> 18761.023 | F32: =E30/SUPUESTOS_PARAMETROS!B19 -> 2.6817787 | G32: Bs/pasajero

Sheet TARIFAS_CATEGORIA
A1: GOBIERNO AUTÓNOMO MUNICIPAL DE SUCRE & ECOTRAFFIC — TARIFAS POR CATEGORÍA SOCIAL
A2: Distribución de Demanda, Tarifas Vigentes, Tarifas Técnicas Equivalentes y Propuesta Social de Negociación
A4: Categoría Social | B4: % Demanda | C4: Viajes / Día | D4: Tarifa Vigente (Bs) | E4: Tarifa Técnica Equiv. (Bs) | F4: Tarifa Social Propuesta (Bs) | G4: Dif. Social - Técnica | H4: Viajes / Mes | I4: Recaudación Vigente / Mes (Bs) | J4: Recaudación Social / Mes (Bs) | K4: Evaluación Técnica
A5: Adultos | B5: 0.58 | C5: =B5*SUPUESTOS_PARAMETROS!$B$13 -> 154030.02 | D5: 4.5 | E5: =COSTOS_OPERACION_COV!$F$32*(D5/$D$11) -> 3.4430825 | F5: 3.5 | G5: =F5-E5 -> 0.05691754 | H5: =C5*SUPUESTOS_PARAMETROS!$B$14 -> 4004780.5 | I5: =H5*D5 -> 18021512 | J5: =H5*F5 -> 14016732 | K5: Base principal de ingresos
A6: Adultos mayores | B6: 0.07 | C6: =B6*SUPUESTOS_PARAMETROS!$B$13 -> 18589.83 | D6: 3.5 | E6: =COSTOS_OPERACION_COV!$F$32*(D6/$D$11) -> 2.677953 | F6: 3 | G6: =F6-E6 -> 0.32204698 | H6: =C6*SUPUESTOS_PARAMETROS!$B$14 -> 483335.58 | I6: =H6*D6 -> 1691674.5 | J6: =H6*F6 -> 1450006.7 | K6: Tarifa preferencial preferida
A7: Universitarios | B7: 0.18 | C7: =B7*SUPUESTOS_PARAMETROS!$B$13 -> 47802.42 | D7: 2.5 | E7: =COSTOS_OPERACION_COV!$F$32*(D7/$D$11) -> 1.9128236 | F7: 2 | G7: =F7-E7 -> 0.087176411 | H7: =C7*SUPUESTOS_PARAMETROS!$B$14 -> 1242862.9 | I7: =H7*D7 -> 3107157.3 | J7: =H7*F7 -> 2485725.8 | K7: Subsidio social a estudiantes sup.
A8: Colegiales | B8: 0.1 | C8: =B8*SUPUESTOS_PARAMETROS!$B$13 -> 26556.9 | D8: 1.5 | E8: =COSTOS_OPERACION_COV!$F$32*(D8/$D$11) -> 1.1476942 | F8: 1.5 | G8: =F8-E8 -> 0.35230585 | H8: =C8*SUPUESTOS_PARAMETROS!$B$14 -> 690479.4 | I8: =H8*D8 -> 1035719.1 | J8: =H8*F8 -> 1035719.1 | K8: Mantiene nivel protegido
A9: Escolares | B9: 0.05 | C9: =B9*SUPUESTOS_PARAMETROS!$B$13 -> 13278.45 | D9: 1 | E9: =COSTOS_OPERACION_COV!$F$32*(D9/$D$11) -> 0.76512944 | F9: 1 | G9: =F9-E9 -> 0.23487056 | H9: =C9*SUPUESTOS_PARAMETROS!$B$14 -> 345239.7 | I9: =H9*D9 -> 345239.7 | J9: =H9*F9 -> 345239.7 | K9: Mantiene nivel escolar inicial
A10: Discapacidad / menores de 5 | B10: 0.02 | C10: =B10*SUPUESTOS_PARAMETROS!$B$13 -> 5311.38 | D10: 0 | E10: =COSTOS_OPERACION_COV!$F$32*(D10/$D$11) -> 0 | F10: 0 | G10: =F10-E10 -> 0 | H10: =C10*SUPUESTOS_PARAMETROS!$B$14 -> 138095.88 | I10: =H10*D10 -> 0 | J10: =H10*F10 -> 0 | K10: Exención legal plena (0 Bs)
A11: TOTAL / PONDERADO: | B11: =SUM(B5:B10) -> 1 | C11: =SUM(C5:C10) -> 265569 | D11: =SUMPRODUCT(B5:B10,D5:D10) -> 3.505 | E11: =COSTOS_OPERACION_COV!$F$32 -> 2.6817787 | F11: =SUMPRODUCT(B5:B10,F5:F10) -> 2.8 | G11: =F11-E11 -> 0.11822133 | H11: =SUM(H5:H10) -> 6904794 | I11: =SUM(I5:I10) -> 24201303 | J11: =SUM(J5:J10) -> 19333423 | K11: Equilibrio de red

Sheet ECONOMIA_PROPIETARIO
A1: GOBIERNO AUTÓNOMO MUNICIPAL DE SUCRE & ECOTRAFFIC — ECONOMÍA DEL TRANSPORTISTA
A2: Doble Cuenta: Flujo Real de Caja del Hogar Propietario vs. Cuenta Económica Regulatoria Oficial v3.2
A4: Concepto Financiero | B4: Tarifa Vigente (Obs.) | C4: Tarifa Técnica (Eq.) | D4: Tarifa Social (Prop.) | E4: Escenario Estrés | F4: Lectura Metodológica
A5: Tarifa ponderada de pasaje (Bs/viaje) | B5: =TARIFAS_CATEGORIA!D11 -> 3.505 | C5: =TARIFAS_CATEGORIA!E11 -> 2.6817787 | D5: =TARIFAS_CATEGORIA!F11 -> 2.8 | E5: =TARIFAS_CATEGORIA!D11 -> 3.505 | F5: Cálculo dinámico
A6: Kilómetros recorridos por unidad/mes | B6: =SUPUESTOS_PARAMETROS!B17 -> 2172.5937 | C6: =SUPUESTOS_PARAMETROS!B17 -> 2172.5937 | D6: =SUPUESTOS_PARAMETROS!B17 -> 2172.5937 | E6: =SUPUESTOS_PARAMETROS!B17 -> 2172.5937 | F6: Cálculo dinámico
A7: Pasajeros transportados por unidad/mes | B7: =SUPUESTOS_PARAMETROS!B19 -> 6995.7386 | C7: =SUPUESTOS_PARAMETROS!B19 -> 6995.7386 | D7: =SUPUESTOS_PARAMETROS!B19 -> 6995.7386 | E7: =SUPUESTOS_PARAMETROS!B19*0.9 -> 6296.1647 | F7: Cálculo dinámico
A8: Recaudación bruta mensual (Bs/mes) | B8: =B5*B7 -> 24520.064 | C8: =C5*C7 -> 18761.023 | D8: =D5*D7 -> 19588.068 | E8: =E5*E7 -> 22068.057 | F8: Cálculo dinámico
A9: Combustible efectivo (Bs/mes) | B9: =COSTOS_OPERACION_COV!E6 -> 8154.1392 | C9: =COSTOS_OPERACION_COV!E6 -> 8154.1392 | D9: =COSTOS_OPERACION_COV!E6 -> 8154.1392 | E9: =COSTOS_OPERACION_COV!E6*1.15 -> 9377.2601 | F9: Cálculo dinámico
A10: Mantenimiento auditado (Bs/mes) | B10: =SUPUESTOS_PARAMETROS!B30 -> 2840.1667 | C10: =SUPUESTOS_PARAMETROS!B30 -> 2840.1667 | D10: =SUPUESTOS_PARAMETROS!B30 -> 2840.1667 | E10: =SUPUESTOS_PARAMETROS!B30 -> 2840.1667 | F10: Cálculo dinámico
A11: Remuneración laboral conductor (Bs/mes) | B11: =COSTOS_OPERACION_COV!E12+COSTOS_OPERACION_COV!E13 -> 3575 | C11: =COSTOS_OPERACION_COV!E12+COSTOS_OPERACION_COV!E13 -> 3575 | D11: =COSTOS_OPERACION_COV!E12+COSTOS_OPERACION_COV!E13 -> 3575 | E11: =COSTOS_OPERACION_COV!E12+COSTOS_OPERACION_COV!E13 -> 3575 | F11: Cálculo dinámico
A12: Otros costos fijos en efectivo (Bs/mes) | B12: =SUM(COSTOS_OPERACION_COV!E14:E20) -> 720.41667 | C12: =SUM(COSTOS_OPERACION_COV!E14:E20) -> 720.41667 | D12: =SUM(COSTOS_OPERACION_COV!E14:E20) -> 720.41667 | E12: =SUM(COSTOS_OPERACION_COV!E14:E20) -> 720.41667 | F12: Cálculo dinámico
A13: OPEX EFECTIVO EN CAJA (Bs/mes) | B13: =SUM(B9:B12) -> 15289.723 | C13: =SUM(C9:C12) -> 15289.723 | D13: =SUM(D9:D12) -> 15289.723 | E13: =SUM(E9:E12) -> 16512.843 | F13: Cálculo dinámico
A14: Excedente operativo de caja (Bs/mes) | B14: =B8-B13 -> 9230.3412 | C14: =C8-C13 -> 3471.3 | D14: =D8-D13 -> 4298.3455 | E14: =E8-E13 -> 5555.214 | F14: Cálculo dinámico
A15: Servicio de deuda individual (Bs/mes) | B15: 0 | C15: 0 | D15: 0 | E15: 0 | F15: Cálculo dinámico
A16: Caja después de deuda (Bs/mes) | B16: =B14-B15 -> 9230.3412 | C16: =C14-C15 -> 3471.3 | D16: =D14-D15 -> 4298.3455 | E16: =E14-E15 -> 5555.214 | F16: Cálculo dinámico
A17: Reserva de reposición / Depreciación (Bs/mes) | B17: =COSTOS_OPERACION_COV!E26 -> 1653 | C17: =COSTOS_OPERACION_COV!E26 -> 1653 | D17: =COSTOS_OPERACION_COV!E26 -> 1653 | E17: =COSTOS_OPERACION_COV!E26 -> 1653 | F17: Cálculo dinámico
A18: CAJA LIBRE DESPUÉS DE RESERVA (Bs/mes) | B18: =B16-B17 -> 7577.3412 | C18: =C16-C17 -> 1818.3 | D18: =D16-D17 -> 2645.3455 | E18: =E16-E17 -> 3902.214 | F18: Cálculo dinámico
A19: Retorno permitido al capital WACC (Bs/mes) | B19: =COSTOS_OPERACION_COV!E27 -> 1818.3 | C19: =COSTOS_OPERACION_COV!E27 -> 1818.3 | D19: =COSTOS_OPERACION_COV!E27 -> 1818.3 | E19: =COSTOS_OPERACION_COV!E27 -> 1818.3 | F19: Cálculo dinámico
A20: UTILIDAD ECONÓMICA EXCEDENTE (Bs/mes) | B20: =B18-B19 -> 5759.0412 | C20: =C18-C19 -> 0 | D20: =D18-D19 -> 827.04551 | E20: =E18-E19 -> 2083.914 | F20: Cálculo dinámico
A21: Remuneración del propietario conductor (Bs/mes) | B21: =B11 -> 3575 | C21: =C11 -> 3575 | D21: =D11 -> 3575 | E21: =E11 -> 3575 | F21: Cálculo dinámico
A22: INGRESO MENSUAL DEL HOGAR PROPIETARIO (Bs/mes) | B22: =B18+B21 -> 11152.341 | C22: =C18+C21 -> 5393.3 | D22: =D18+D21 -> 6220.3455 | E22: =E18+E21 -> 7477.214 | F22: Cálculo dinámico
A23: Retorno total anual sobre activo invertido | B23: =(B19*12+B20*12)/SUPUESTOS_PARAMETROS!$B$33 -> 0.45839935 | C23: =(C19*12+C20*12)/SUPUESTOS_PARAMETROS!$B$33 -> 0.11 | D23: =(D19*12+D20*12)/SUPUESTOS_PARAMETROS!$B$33 -> 0.160033 | E23: =(E19*12+E20*12)/SUPUESTOS_PARAMETROS!$B$33 -> 0.2360686 | F23: Cálculo dinámico
A24: Punto de equilibrio mensual (Pasajeros/mes) | B24: =COSTOS_OPERACION_COV!$E$30/B5 -> 5352.6455 | C24: =COSTOS_OPERACION_COV!$E$30/C5 -> 6995.7386 | D24: =COSTOS_OPERACION_COV!$E$30/D5 -> 6700.3652 | E24: =COSTOS_OPERACION_COV!$E$30/E5 -> 5352.6455 | F24: Cálculo dinámico
A25: Punto de equilibrio diario (Pasajeros/día) | B25: =B24/SUPUESTOS_PARAMETROS!$B$14 -> 205.87098 | C25: =C24/SUPUESTOS_PARAMETROS!$B$14 -> 269.06687 | D25: =D24/SUPUESTOS_PARAMETROS!$B$14 -> 257.70635 | E25: =E24/SUPUESTOS_PARAMETROS!$B$14 -> 205.87098 | F25: Cálculo dinámico
A26: IPK de equilibrio técnico | B26: =B24/B6 -> 2.4637121 | C26: =C24/C6 -> 3.2199939 | D26: =D24/D6 -> 3.0840397 | E26: =E24/E6 -> 2.4637121 | F26: Cálculo dinámico

Sheet RENTABILIDAD_32_RUTAS
A1: GOBIERNO AUTÓNOMO MUNICIPAL DE SUCRE & ECOTRAFFIC — RENTABILIDAD DE LAS 32 RUTAS
A2: Asignación de Kilometraje, Demanda, Costos y Utilidad por Línea | Factor de Conciliación de Red
A4: Vueltas/día escenario: | B4: =SUPUESTOS_PARAMETROS!B15 -> 3 | D4: km implícitos rutas: | E4: =SUMPRODUCT(D7:D38,F7:F38)*B4 -> 82066.487 | G4: km auditados red: | H4: =SUPUESTOS_PARAMETROS!B12 -> 82475 | J4: Factor de Conciliación: | K4: =H4/E4 -> 1.0049778
A6: ID | B6: Sindicato | C6: Línea de Transporte | D6: Distancia Ciclo (km) | E6: Flota Inventario | F6: Flota Activa Asignada | G6: Vueltas / Día | H6: Factor Concil. | I6: km / Unidad / Mes | J6: Pasajeros / Unidad / Mes | K6: Ingreso Neto Vigente (Bs) | L6: Ingreso Neto Social (Bs) | M6: OPEX Efectivo (Bs) | N6: Reserva Reposición (Bs) | O6: Utilidad Econ. Vigente (Bs) | P6: Utilidad Econ. Social (Bs) | Q6: Estado Semáforo
A7: 1 | B7: San Cristóbal | C7: Línea 12 amarillo | D7: 15.49 | E7: 27 | F7: 30.490847 | G7: =$B$4 -> 3 | H7: =$K$4 -> 1.0049778 | I7: =D7*G7*H7*SUPUESTOS_PARAMETROS!$B$14 -> 1214.2343 | J7: =I7*SUPUESTOS_PARAMETROS!$B$20 -> 3909.8272 | K7: =J7*TARIFAS_CATEGORIA!$D$11 -> 13703.944 | L7: =J7*TARIFAS_CATEGORIA!$F$11 -> 10947.516 | M7: =(I7/SUPUESTOS_PARAMETROS!$B$27)*SUPUESTOS_PARAMETROS!$B$29*(1+SUPUESTOS_PARAMETROS!$B$28)+COSTOS_OPERACION_COV!$E$7*(I7/SUPUESTOS_PARAMETROS!$B$17)+COSTOS_OPERACION_COV!$E$11+COSTOS_OPERACION_COV!$E$12+COSTOS_OPERACION_COV!$E$13+SUM(COSTOS_OPERACION_COV!$E$14:$E$20) -> 11377.896 | N7: =COSTOS_OPERACION_COV!$E$26 -> 1653 | O7: =K7-M7-N7-COSTOS_OPERACION_COV!$E$27 -> -1145.2517 | P7: =L7-M7-N7-COSTOS_OPERACION_COV!$E$27 -> -3901.6799 | Q7: =IF(O7>=0,"CUBRE COSTO","DÉFICIT") -> DÉFICIT
A8: 2 | B8: San Cristóbal | C8: Línea 12 Rosado | D8: 29.24 | E8: 23 | F8: 25.973684 | G8: =$B$4 -> 3 | H8: =$K$4 -> 1.0049778 | I8: =D8*G8*H8*SUPUESTOS_PARAMETROS!$B$14 -> 2292.073 | J8: =I8*SUPUESTOS_PARAMETROS!$B$20 -> 7380.4613 | K8: =J8*TARIFAS_CATEGORIA!$D$11 -> 25868.517 | L8: =J8*TARIFAS_CATEGORIA!$F$11 -> 20665.292 | M8: =(I8/SUPUESTOS_PARAMETROS!$B$27)*SUPUESTOS_PARAMETROS!$B$29*(1+SUPUESTOS_PARAMETROS!$B$28)+COSTOS_OPERACION_COV!$E$7*(I8/SUPUESTOS_PARAMETROS!$B$17)+COSTOS_OPERACION_COV!$E$11+COSTOS_OPERACION_COV!$E$12+COSTOS_OPERACION_COV!$E$13+SUM(COSTOS_OPERACION_COV!$E$14:$E$20) -> 15777.413 | N8: =COSTOS_OPERACION_COV!$E$26 -> 1653 | O8: =K8-M8-N8-COSTOS_OPERACION_COV!$E$27 -> 6619.8042 | P8: =L8-M8-N8-COSTOS_OPERACION_COV!$E$27 -> 1416.579 | Q8: =IF(O8>=0,"CUBRE COSTO","DÉFICIT") -> CUBRE COSTO
A9: 3 | B9: San Cristóbal | C9: Línea 1 | D9: 30.62 | E9: 28 | F9: 31.620137 | G9: =$B$4 -> 3 | H9: =$K$4 -> 1.0049778 | I9: =D9*G9*H9*SUPUESTOS_PARAMETROS!$B$14 -> 2400.2489 | J9: =I9*SUPUESTOS_PARAMETROS!$B$20 -> 7728.7868 | K9: =J9*TARIFAS_CATEGORIA!$D$11 -> 27089.398 | L9: =J9*TARIFAS_CATEGORIA!$F$11 -> 21640.603 | M9: =(I9/SUPUESTOS_PARAMETROS!$B$27)*SUPUESTOS_PARAMETROS!$B$29*(1+SUPUESTOS_PARAMETROS!$B$28)+COSTOS_OPERACION_COV!$E$7*(I9/SUPUESTOS_PARAMETROS!$B$17)+COSTOS_OPERACION_COV!$E$11+COSTOS_OPERACION_COV!$E$12+COSTOS_OPERACION_COV!$E$13+SUM(COSTOS_OPERACION_COV!$E$14:$E$20) -> 16218.964 | N9: =COSTOS_OPERACION_COV!$E$26 -> 1653 | O9: =K9-M9-N9-COSTOS_OPERACION_COV!$E$27 -> 7399.1335 | P9: =L9-M9-N9-COSTOS_OPERACION_COV!$E$27 -> 1950.3388 | Q9: =IF(O9>=0,"CUBRE COSTO","DÉFICIT") -> CUBRE COSTO
A10: 4 | B10: San Cristóbal | C10: Línea 2 | D10: 32.9 | E10: 28 | F10: 31.620137 | G10: =$B$4 -> 3 | H10: =$K$4 -> 1.0049778 | I10: =D10*G10*H10*SUPUESTOS_PARAMETROS!$B$14 -> 2578.9741 | J10: =I10*SUPUESTOS_PARAMETROS!$B$20 -> 8304.281 | K10: =J10*TARIFAS_CATEGORIA!$D$11 -> 29106.505 | L10: =J10*TARIFAS_CATEGORIA!$F$11 -> 23251.987 | M10: =(I10/SUPUESTOS_PARAMETROS!$B$27)*SUPUESTOS_PARAMETROS!$B$29*(1+SUPUESTOS_PARAMETROS!$B$28)+COSTOS_OPERACION_COV!$E$7*(I10/SUPUESTOS_PARAMETROS!$B$17)+COSTOS_OPERACION_COV!$E$11+COSTOS_OPERACION_COV!$E$12+COSTOS_OPERACION_COV!$E$13+SUM(COSTOS_OPERACION_COV!$E$14:$E$20) -> 16948.484 | N10: =COSTOS_OPERACION_COV!$E$26 -> 1653 | O10: =K10-M10-N10-COSTOS_OPERACION_COV!$E$27 -> 8686.7209 | P10: =L10-M10-N10-COSTOS_OPERACION_COV!$E$27 -> 2832.2028 | Q10: =IF(O10>=0,"CUBRE COSTO","DÉFICIT") -> CUBRE COSTO
A11: 5 | B11: San Cristóbal | C11: Línea 3 | D11: 28.3 | E11: 29 | F11: 32.749428 | G11: =$B$4 -> 3 | H11: =$K$4 -> 1.0049778 | I11: =D11*G11*H11*SUPUESTOS_PARAMETROS!$B$14 -> 2218.3881 | J11: =I11*SUPUESTOS_PARAMETROS!$B$20 -> 7143.1962 | K11: =J11*TARIFAS_CATEGORIA!$D$11 -> 25036.903 | L11: =J11*TARIFAS_CATEGORIA!$F$11 -> 20000.949 | M11: =(I11/SUPUESTOS_PARAMETROS!$B$27)*SUPUESTOS_PARAMETROS!$B$29*(1+SUPUESTOS_PARAMETROS!$B$28)+COSTOS_OPERACION_COV!$E$7*(I11/SUPUESTOS_PARAMETROS!$B$17)+COSTOS_OPERACION_COV!$E$11+COSTOS_OPERACION_COV!$E$12+COSTOS_OPERACION_COV!$E$13+SUM(COSTOS_OPERACION_COV!$E$14:$E$20) -> 15476.646 | N11: =COSTOS_OPERACION_COV!$E$26 -> 1653 | O11: =K11-M11-N11-COSTOS_OPERACION_COV!$E$27 -> 6088.9568 | P11: =L11-M11-N11-COSTOS_OPERACION_COV!$E$27 -> 1053.0035 | Q11: =IF(O11>=0,"CUBRE COSTO","DÉFICIT") -> CUBRE COSTO
A12: 6 | B12: San Cristóbal | C12: Línea 4 | D12: 29.76 | E12: 28 | F12: 31.620137 | G12: =$B$4 -> 3 | H12: =$K$4 -> 1.0049778 | I12: =D12*G12*H12*SUPUESTOS_PARAMETROS!$B$14 -> 2332.835 | J12: =I12*SUPUESTOS_PARAMETROS!$B$20 -> 7511.7144 | K12: =J12*TARIFAS_CATEGORIA!$D$11 -> 26328.559 | L12: =J12*TARIFAS_CATEGORIA!$F$11 -> 21032.8 | M12: =(I12/SUPUESTOS_PARAMETROS!$B$27)*SUPUESTOS_PARAMETROS!$B$29*(1+SUPUESTOS_PARAMETROS!$B$28)+COSTOS_OPERACION_COV!$E$7*(I12/SUPUESTOS_PARAMETROS!$B$17)+COSTOS_OPERACION_COV!$E$11+COSTOS_OPERACION_COV!$E$12+COSTOS_OPERACION_COV!$E$13+SUM(COSTOS_OPERACION_COV!$E$14:$E$20) -> 15943.794 | N12: =COSTOS_OPERACION_COV!$E$26 -> 1653 | O12: =K12-M12-N12-COSTOS_OPERACION_COV!$E$27 -> 6913.4645 | P12: =L12-M12-N12-COSTOS_OPERACION_COV!$E$27 -> 1617.7059 | Q12: =IF(O12>=0,"CUBRE COSTO","DÉFICIT") -> CUBRE COSTO
A13: 7 | B13: San Cristóbal | C13: Línea 5 | D13: 25.92 | E13: 29 | F13: 32.749428 | G13: =$B$4 -> 3 | H13: =$K$4 -> 1.0049778 | I13: =D13*G13*H13*SUPUESTOS_PARAMETROS!$B$14 -> 2031.824 | J13: =I13*SUPUESTOS_PARAMETROS!$B$20 -> 6542.4609 | K13: =J13*TARIFAS_CATEGORIA!$D$11 -> 22931.326 | L13: =J13*TARIFAS_CATEGORIA!$F$11 -> 18318.891 | M13: =(I13/SUPUESTOS_PARAMETROS!$B$27)*SUPUESTOS_PARAMETROS!$B$29*(1+SUPUESTOS_PARAMETROS!$B$28)+COSTOS_OPERACION_COV!$E$7*(I13/SUPUESTOS_PARAMETROS!$B$17)+COSTOS_OPERACION_COV!$E$11+COSTOS_OPERACION_COV!$E$12+COSTOS_OPERACION_COV!$E$13+SUM(COSTOS_OPERACION_COV!$E$14:$E$20) -> 14715.129 | N13: =COSTOS_OPERACION_COV!$E$26 -> 1653 | O13: =K13-M13-N13-COSTOS_OPERACION_COV!$E$27 -> 4744.8962 | P13: =L13-M13-N13-COSTOS_OPERACION_COV!$E$27 -> 132.46121 | Q13: =IF(O13>=0,"CUBRE COSTO","DÉFICIT") -> CUBRE COSTO
A14: 8 | B14: San Cristóbal | C14: Línea 6 | D14: 26.38 | E14: 28 | F14: 31.620137 | G14: =$B$4 -> 3 | H14: =$K$4 -> 1.0049778 | I14: =D14*G14*H14*SUPUESTOS_PARAMETROS!$B$14 -> 2067.8826 | J14: =I14*SUPUESTOS_PARAMETROS!$B$20 -> 6658.5694 | K14: =J14*TARIFAS_CATEGORIA!$D$11 -> 23338.286 | L14: =J14*TARIFAS_CATEGORIA!$F$11 -> 18643.994 | M14: =(I14/SUPUESTOS_PARAMETROS!$B$27)*SUPUESTOS_PARAMETROS!$B$29*(1+SUPUESTOS_PARAMETROS!$B$28)+COSTOS_OPERACION_COV!$E$7*(I14/SUPUESTOS_PARAMETROS!$B$17)+COSTOS_OPERACION_COV!$E$11+COSTOS_OPERACION_COV!$E$12+COSTOS_OPERACION_COV!$E$13+SUM(COSTOS_OPERACION_COV!$E$14:$E$20) -> 14862.313 | N14: =COSTOS_OPERACION_COV!$E$26 -> 1653 | O14: =K14-M14-N14-COSTOS_OPERACION_COV!$E$27 -> 5004.6726 | P14: =L14-M14-N14-COSTOS_OPERACION_COV!$E$27 -> 310.38114 | Q14: =IF(O14>=0,"CUBRE COSTO","DÉFICIT") -> CUBRE COSTO
A15: 9 | B15: San Cristóbal | C15: Línea 7 | D15: 24.5 | E15: 28 | F15: 31.620137 | G15: =$B$4 -> 3 | H15: =$K$4 -> 1.0049778 | I15: =D15*G15*H15*SUPUESTOS_PARAMETROS!$B$14 -> 1920.5126 | J15: =I15*SUPUESTOS_PARAMETROS!$B$20 -> 6184.0391 | K15: =J15*TARIFAS_CATEGORIA!$D$11 -> 21675.057 | L15: =J15*TARIFAS_CATEGORIA!$F$11 -> 17315.309 | M15: =(I15/SUPUESTOS_PARAMETROS!$B$27)*SUPUESTOS_PARAMETROS!$B$29*(1+SUPUESTOS_PARAMETROS!$B$28)+COSTOS_OPERACION_COV!$E$7*(I15/SUPUESTOS_PARAMETROS!$B$17)+COSTOS_OPERACION_COV!$E$11+COSTOS_OPERACION_COV!$E$12+COSTOS_OPERACION_COV!$E$13+SUM(COSTOS_OPERACION_COV!$E$14:$E$20) -> 14260.779 | N15: =COSTOS_OPERACION_COV!$E$26 -> 1653 | O15: =K15-M15-N15-COSTOS_OPERACION_COV!$E$27 -> 3942.9777 | P15: =L15-M15-N15-COSTOS_OPERACION_COV!$E$27 -> -416.76989 | Q15: =IF(O15>=0,"CUBRE COSTO","DÉFICIT") -> CUBRE COSTO
A16: 10 | B16: San Cristóbal | C16: Línea 8 | D16: 25.83 | E16: 29 | F16: 32.749428 | G16: =$B$4 -> 3 | H16: =$K$4 -> 1.0049778 | I16: =D16*G16*H16*SUPUESTOS_PARAMETROS!$B$14 -> 2024.769 | J16: =I16*SUPUESTOS_PARAMETROS!$B$20 -> 6519.744 | K16: =J16*TARIFAS_CATEGORIA!$D$11 -> 22851.703 | L16: =J16*TARIFAS_CATEGORIA!$F$11 -> 18255.283 | M16: =(I16/SUPUESTOS_PARAMETROS!$B$27)*SUPUESTOS_PARAMETROS!$B$29*(1+SUPUESTOS_PARAMETROS!$B$28)+COSTOS_OPERACION_COV!$E$7*(I16/SUPUESTOS_PARAMETROS!$B$17)+COSTOS_OPERACION_COV!$E$11+COSTOS_OPERACION_COV!$E$12+COSTOS_OPERACION_COV!$E$13+SUM(COSTOS_OPERACION_COV!$E$14:$E$20) -> 14686.333 | N16: =COSTOS_OPERACION_COV!$E$26 -> 1653 | O16: =K16-M16-N16-COSTOS_OPERACION_COV!$E$27 -> 4694.0703 | P16: =L16-M16-N16-COSTOS_OPERACION_COV!$E$27 -> 97.650789 | Q16: =IF(O16>=0,"CUBRE COSTO","DÉFICIT") -> CUBRE COSTO
A17: 11 | B17: San Cristóbal | C17: Línea 10 | D17: 35.53 | E17: 27 | F17: 30.490847 | G17: =$B$4 -> 3 | H17: =$K$4 -> 1.0049778 | I17: =D17*G17*H17*SUPUESTOS_PARAMETROS!$B$14 -> 2785.1353 | J17: =I17*SUPUESTOS_PARAMETROS!$B$20 -> 8968.1187 | K17: =J17*TARIFAS_CATEGORIA!$D$11 -> 31433.256 | L17: =J17*TARIFAS_CATEGORIA!$F$11 -> 25110.732 | M17: =(I17/SUPUESTOS_PARAMETROS!$B$27)*SUPUESTOS_PARAMETROS!$B$29*(1+SUPUESTOS_PARAMETROS!$B$28)+COSTOS_OPERACION_COV!$E$7*(I17/SUPUESTOS_PARAMETROS!$B$17)+COSTOS_OPERACION_COV!$E$11+COSTOS_OPERACION_COV!$E$12+COSTOS_OPERACION_COV!$E$13+SUM(COSTOS_OPERACION_COV!$E$14:$E$20) -> 17789.992 | N17: =COSTOS_OPERACION_COV!$E$26 -> 1653 | O17: =K17-M17-N17-COSTOS_OPERACION_COV!$E$27 -> 10171.964 | P17: =L17-M17-N17-COSTOS_OPERACION_COV!$E$27 -> 3849.4407 | Q17: =IF(O17>=0,"CUBRE COSTO","DÉFICIT") -> CUBRE COSTO
A18: 12 | B18: San Cristóbal | C18: Línea 11 | D18: 22.96 | E18: 26 | F18: 29.361556 | G18: =$B$4 -> 3 | H18: =$K$4 -> 1.0049778 | I18: =D18*G18*H18*SUPUESTOS_PARAMETROS!$B$14 -> 1799.7947 | J18: =I18*SUPUESTOS_PARAMETROS!$B$20 -> 5795.328 | K18: =J18*TARIFAS_CATEGORIA!$D$11 -> 20312.625 | L18: =J18*TARIFAS_CATEGORIA!$F$11 -> 16226.919 | M18: =(I18/SUPUESTOS_PARAMETROS!$B$27)*SUPUESTOS_PARAMETROS!$B$29*(1+SUPUESTOS_PARAMETROS!$B$28)+COSTOS_OPERACION_COV!$E$7*(I18/SUPUESTOS_PARAMETROS!$B$17)+COSTOS_OPERACION_COV!$E$11+COSTOS_OPERACION_COV!$E$12+COSTOS_OPERACION_COV!$E$13+SUM(COSTOS_OPERACION_COV!$E$14:$E$20) -> 13768.033 | N18: =COSTOS_OPERACION_COV!$E$26 -> 1653 | O18: =K18-M18-N18-COSTOS_OPERACION_COV!$E$27 -> 3073.2914 | P18: =L18-M18-N18-COSTOS_OPERACION_COV!$E$27 -> -1012.4149 | Q18: =IF(O18>=0,"CUBRE COSTO","DÉFICIT") -> CUBRE COSTO
... A38: 32 | B38: Sindicato Sucre | C38: Línea D 87 | D38: 26 | E38: 27 | F38: 30.490847 | G38: =$B$4 -> 3 | H38: =$K$4 -> 1.0049778 | I38: =D38*G38*H38*SUPUESTOS_PARAMETROS!$B$14 -> 2038.0951 | J38: =I38*SUPUESTOS_PARAMETROS!$B$20 -> 6562.6537 | K38: =J38*TARIFAS_CATEGORIA!$D$11 -> 23002.101 | L38: =J38*TARIFAS_CATEGORIA!$F$11 -> 18375.43 | M38: =(I38/SUPUESTOS_PARAMETROS!$B$27)*SUPUESTOS_PARAMETROS!$B$29*(1+SUPUESTOS_PARAMETROS!$B$28)+COSTOS_OPERACION_COV!$E$7*(I38/SUPUESTOS_PARAMETROS!$B$17)+COSTOS_OPERACION_COV!$E$11+COSTOS_OPERACION_COV!$E$12+COSTOS_OPERACION_COV!$E$13+SUM(COSTOS_OPERACION_COV!$E$14:$E$20) -> 14740.727 | N38: =COSTOS_OPERACION_COV!$E$26 -> 1653 | O38: =K38-M38-N38-COSTOS_OPERACION_COV!$E$27 -> 4790.0747 | P38: =L38-M38-N38-COSTOS_OPERACION_COV!$E$27 -> 163.40381 | Q38: =IF(O38>=0,"CUBRE COSTO","DÉFICIT") -> CUBRE COSTO
A39: TOTAL SISTEMA: | E39: =SUM(E7:E38) -> 874 | F39: =SUM(F7:F38) -> 987 | I39: =AVERAGE(I7:I38) -> 2172.8494 | J39: =AVERAGE(J7:J38) -> 6996.5619 | K39: =AVERAGE(K7:K38) -> 24522.949 | L39: =AVERAGE(L7:L38) -> 19590.373 | M39: =AVERAGE(M7:M38) -> 15290.766 | N39: =AVERAGE(N7:N38) -> 1653 | O39: =AVERAGE(O7:O38) -> 5760.8831 | P39: =AVERAGE(P7:P38) -> 828.30703 | Q39: =COUNTIF(Q7:Q38,"DÉFICIT")&" deficitarias" -> 1 deficitarias

Sheet REGLA_ACTUALIZACION
A1: GOBIERNO AUTÓNOMO MUNICIPAL DE SUCRE & ECOTRAFFIC — FÓRMULA DE REAJUSTE TARIFARIO
A2: Índice Paramétrico Laspeyres de Costos de Transporte Urbano | Gobernanza y Revisión Trimestral
A4: CANASTA PONDERADA DE COSTOS AUDITADOS (ESTRUCTURA BASE 100%)
A5: Insumo / Componente | B5: Costo Mensual Base (Bs) | C5: Ponderación (alpha) | D5: Índice Base | E5: Índice Actual | F5: Relativo (I_t / I_0) | G5: Aporte al Reajuste | H5: Fuente Oficial Trimestral
A6: Combustible (Diésel) | B6: =COSTOS_OPERACION_COV!E6 -> 8154.1392 | C6: =B6/$B$11 -> 0.43463192 | D6: 100 | E6: 100 | F6: =E6/D6 -> 1 | G6: =C6*F6 -> 0.43463192 | H6: Precio oficial regulado de YPFB / ANH
A7: Trabajo (Personal conducción) | B7: =COSTOS_OPERACION_COV!E12+COSTOS_OPERACION_COV!E13 -> 3575 | C7: =B7/$B$11 -> 0.19055465 | D7: 100 | E7: 100 | F7: =E7/D7 -> 1 | G7: =C7*F7 -> 0.19055465 | H7: Decreto de Salario Mínimo Nacional / Convenio
A8: Mantenimiento y Repuestos | B8: =COSTOS_OPERACION_COV!E7+COSTOS_OPERACION_COV!E11 -> 2840.1667 | C8: =B8/$B$11 -> 0.15138656 | D8: 100 | E8: 100 | F8: =E8/D8 -> 1 | G8: =C8*F8 -> 0.15138656 | H8: Canasta técnica municipal de 52 insumos Nissan
A9: Otros Costos Fijos Administrativos | B9: =SUM(COSTOS_OPERACION_COV!E14:E20) -> 720.41667 | C9: =B9/$B$11 -> 0.038399648 | D9: 100 | E9: 100 | F9: =E9/D9 -> 1 | G9: =C9*F9 -> 0.038399648 | H9: Índice de Precios al Consumidor (IPC General INE)
A10: Costo de Capital (Depreciación + WACC) | B10: =COSTOS_OPERACION_COV!E28 -> 3471.3 | C10: =B10/$B$11 -> 0.18502723 | D10: 100 | E10: 100 | F10: =E10/D10 -> 1 | G10: =C10*F10 -> 0.18502723 | H10: Tasa activa bancaria regulada BCB / ASFI
A11: TOTAL COSTO AUDITADO (BASE 100%): | B11: =SUM(B6:B10) -> 18761.023 | C11: =SUM(C6:C10) -> 1 | G11: =SUM(G6:G10) -> 1
A13: MECANISMO DE ACTIVACIÓN TRIMESTRAL Y GOBERNANZA
A14: Índice de Costos Acumulado Actual (I_t) | B14: =G11 -> 1 | C14: factor | D14: Suma ponderada de relativos de insumos
A15: Variación Acumulada de Costos | B15: =G11-1 -> 0 | C15: % variación | D15: Diferencia relativa respecto a la base
A16: Umbral de Activación Simétrico | B16: =SUPUESTOS_PARAMETROS!B37 -> 0.05 | C16: % umbral | D16: Acuerdo regulatorio de activación (±5%)
A17: Decisión Técnica Regulatoria | B17: =IF(ABS(B15)>=B16, "REVISAR TARIFA EN COMISIÓN MIXTA", "MANTENER TARIFA VIGENTE") -> MANTENER TARIFA VIGENTE | C17: dictamen | D17: Filtro anti-volatilidad para estabilidad ciudadana
A18: Tarifa Técnica Auditada Vigente | B18: =COSTOS_OPERACION_COV!F32 -> 2.6817787 | C18: Bs/viaje | D18: Tarifa de costo actual
A19: Tarifa Técnica Indexada Resultante | B19: =B18*B14 -> 2.6817787 | C19: Bs/viaje | D19: Tarifa resultante tras aplicación del índice

Sheet ESCENARIOS_NEGOCIACION
A1: GOBIERNO AUTÓNOMO MUNICIPAL DE SUCRE & ECOTRAFFIC — MATRIZ DE ESCENARIOS DE NEGOCIACIÓN
A2: Comparación Homogénea de Ingresos, Costos, Rentabilidad e Impacto Social | Base Técnica Oficial
A4: Escenario de Negociación | B4: Flota Activa | C4: Demanda (pax/día) | D4: km Red / Día | E4: Rend. (km/l) | F4: Conductores | G4: Tarifa Pond. (Bs) | H4: Ingreso Neto / Unidad (Bs) | I4: Costo Regulatorio / Unidad (Bs) | J4: Ingreso Hogar Propietario (Bs) | K4: Utilidad Excedente (Bs) | L4: Tarifa Técnica (Bs) | M4: Dictamen Técnico
A5: 1. Vigente Observado | B5: =SUPUESTOS_PARAMETROS!B11 -> 987 | C5: =SUPUESTOS_PARAMETROS!B13 -> 265569 | D5: =SUPUESTOS_PARAMETROS!B12 -> 82475 | E5: =SUPUESTOS_PARAMETROS!B27 -> 5.5 | F5: 1 | G5: =TARIFAS_CATEGORIA!D11 -> 3.505 | H5: =ECONOMIA_PROPIETARIO!B8 -> 24520.064 | I5: =COSTOS_OPERACION_COV!E30 -> 18761.023 | J5: =ECONOMIA_PROPIETARIO!B22 -> 11152.341 | K5: =ECONOMIA_PROPIETARIO!B20 -> 5759.0412 | L5: =COSTOS_OPERACION_COV!F32 -> 2.6817787 | M5: Tarifa actual con sobreganancia económica
A6: 2. Tarifa Técnica de Equilibrio | B6: =SUPUESTOS_PARAMETROS!B11 -> 987 | C6: =SUPUESTOS_PARAMETROS!B13 -> 265569 | D6: =SUPUESTOS_PARAMETROS!B12 -> 82475 | E6: =SUPUESTOS_PARAMETROS!B27 -> 5.5 | F6: 1 | G6: =TARIFAS_CATEGORIA!E11 -> 2.6817787 | H6: =ECONOMIA_PROPIETARIO!C8 -> 18761.023 | I6: =COSTOS_OPERACION_COV!E30 -> 18761.023 | J6: =ECONOMIA_PROPIETARIO!C22 -> 5393.3 | K6: =ECONOMIA_PROPIETARIO!C20 -> 0 | L6: =COSTOS_OPERACION_COV!F32 -> 2.6817787 | M6: Equilibrio financiero exacto (utilidad = 0)
A7: 3. Sobrecosto Combustible (+15%) y Demanda (-10%) | B7: =SUPUESTOS_PARAMETROS!B11 -> 987 | C7: =SUPUESTOS_PARAMETROS!B13*0.9 -> 239012.1 | D7: =SUPUESTOS_PARAMETROS!B12 -> 82475 | E7: =SUPUESTOS_PARAMETROS!B27/1.15 -> 4.7826087 | F7: 1 | G7: =TARIFAS_CATEGORIA!D11 -> 3.505 | H7: =ECONOMIA_PROPIETARIO!E8 -> 22068.057 | I7: =COSTOS_OPERACION_COV!E30-COSTOS_OPERACION_COV!E6+COSTOS_OPERACION_COV!E6*1.15 -> 19984.143 | J7: =ECONOMIA_PROPIETARIO!E22 -> 7477.214 | K7: =ECONOMIA_PROPIETARIO!E20 -> 2083.914 | L7: =I7/(C7*SUPUESTOS_PARAMETROS!$B$14/B7) -> 3.1740185 | M7: Estrés severo de costos: aún cubre costos
A8: 4. Turno Doble Conducción (TDR: 2 Choferes) | B8: =SUPUESTOS_PARAMETROS!B11 -> 987 | C8: =SUPUESTOS_PARAMETROS!B13 -> 265569 | D8: =SUPUESTOS_PARAMETROS!B12 -> 82475 | E8: =SUPUESTOS_PARAMETROS!B27 -> 5.5 | F8: 2 | G8: =TARIFAS_CATEGORIA!D11 -> 3.505 | H8: =ECONOMIA_PROPIETARIO!B8 -> 24520.064 | I8: =COSTOS_OPERACION_COV!E30+COSTOS_OPERACION_COV!E12+COSTOS_OPERACION_COV!E13 -> 22336.023 | J8: =ECONOMIA_PROPIETARIO!B22-COSTOS_OPERACION_COV!E12-COSTOS_OPERACION_COV!E13 -> 7577.3412 | K8: =H8-I8 -> 2184.0412 | L8: =I8/SUPUESTOS_PARAMETROS!$B$19 -> 3.1928041 | M8: Requerimiento TDR: absorbe segundo chofer
A9: 5. Eficiencia Operacional (Flota 800 unidades) | B9: 800 | C9: 273000 | D9: 85317 | E9: 4.8 | F9: 1 | G9: =TARIFAS_CATEGORIA!D11 -> 3.505 | H9: =(C9*SUPUESTOS_PARAMETROS!$B$14/B9)*G9 -> 31098.112 | I9: =(D9*SUPUESTOS_PARAMETROS!$B$14/B9)/5.5*SUPUESTOS_PARAMETROS!$B$29*1.15+COSTOS_OPERACION_COV!$E$7*((D9*SUPUESTOS_PARAMETROS!$B$14/B9)/SUPUESTOS_PARAMETROS!$B$17)+COSTOS_OPERACION_COV!$E$11+COSTOS_OPERACION_COV!$E$12+COSTOS_OPERACION_COV!$E$13+SUM(COSTOS_OPERACION_COV!$E$14:$E$20)+COSTOS_OPERACION_COV!$E$28 -> 21210.952 | J9: =H9-I9+COSTOS_OPERACION_COV!$E$12 -> 13187.161 | K9: =H9-I9 -> 9887.1607 | L9: =I9/(C9*SUPUESTOS_PARAMETROS!$B$14/B9) -> 2.3906398 | M9: Flota racionalizada: menor tarifa requerida

Sheet FUENTES_AUDITORIA_CONTROL
A1: GOBIERNO AUTÓNOMO MUNICIPAL DE SUCRE & ECOTRAFFIC — MATRIZ DE AUDITORÍA Y CONTROL
A2: Estado Técnico de Validación de Supuestos: Puntos Cerrados Auditados vs. Puntos Abiertos de Concertación
A4: 1. PUNTOS TÉCNICOS AUDITADOS Y CERRADOS CON LA VERSIÓN v3.2
A5: Variable / Rubro | B5: Dato Anterior (v3.1) | C5: Dato Auditado Cerrado (v3.2) | D5: Impacto Técnico | E5: Estado | F5: Evidencia de Respaldo | G5: Responsable Técnico
A6: Mantenimiento y Repuestos | B6: Bs. 4.266,02/mes | C6: Bs. 2.869,75/mes | D6: -32,7% (-Bs. 1.396,27/mes) en costo COV | E6: CERRADO | F6: Planilla técnica oficial v2 (52 ítems Nissan) | G6: Auditoría Técnica Ecotraffic
A7: Rendimiento Diésel | B7: 2,94 vs 3,50 vs 4,50 km/l | C7: 5,50 km/l (+15% ralentí urbano) | D7: Consumo auditado: 4,78 km/l efectivo | E7: CERRADO | F7: Prueba de consumo en ruta urbana cerrada | G7: Comisión Técnica Mixta
A8: Producción de Red | B8: Dispersa (82.066 a 85.317 km) | C8: 82.475,00 km/día | D8: Producción física base consolidada | E8: CERRADO | F8: Consolidación satelital GPS de 30 días | G8: Auditoría de Transporte
A9: Demanda Total Diaria | B9: 273.000 vs 265.569 pax | C9: 265.569 pasajeros/día | D9: Base de pasajeros pagos equivalentes | E9: CERRADO | F9: Aforo clasificado en puntos de máxima carga | G9: Consultora / GAM Sucre
A11: 2. PUNTOS ABIERTOS EN LA MESA DE CONCERTACIÓN Y NEGOCIACIÓN (GAM SUCRE — SINDICATOS)
A12: Variable en Negociación | B12: Postura A (Sindicatos) | C12: Postura B (Municipio / Técnico) | D12: Impacto en Tarifa Técnica | E12: Estado | F12: Evidencia Exigida | G12: Mesa Responsable
A13: Flota Activa Operativa | B13: 987 a 1.003 vehículos | C13: 874 vehículos (inventario patentes) | D13: Alto: define el costo fijo por unidad y oferta | E13: ABIERTO | F13: Padrón biométrico + control GPS de encendido diario | G13: Mesa 1: Flota y Operación
A14: Vueltas / Día por Unidad | B14: 3,00 vueltas/día (despacho) | C14: 3,50 vueltas/día (programación teórica) | D14: Medio: altera el kilometraje unitario y frecuencia | E14: ABIERTO | F14: Registros de hoja de ruta en cabeceras de línea | G14: Mesa 1: Flota y Operación
A15: Índice Pasajeros/Km (IPK) | B15: 2,20 pax/km (afirmación gremial) | C15: 3,22 pax/km (aforo observado red) | D15: Crítico: cambia la recaudación en ±31% | E15: ABIERTO | F15: Aforos simultáneos y validación electrónica de caja | G15: Mesa 2: Demanda e Ingresos
A16: Régimen de Conducción | B16: 2 choferes (2 x Bs. 2.800) | C16: 1 chofer (1 x Bs. 3.300 + aguinaldo) | D16: Alto: incrementa costo laboral en Bs. 3.000+/mes | E16: ABIERTO | F16: Inspección de turnos y planillas Ministerio Trabajo | G16: Mesa 3: Régimen Laboral

Sheet METODOLOGIA_GLOSARIO
A1: GOBIERNO AUTÓNOMO MUNICIPAL DE SUCRE & ECOTRAFFIC — METODOLOGÍA Y GLOSARIO DE FÓRMULAS
A2: Guía Conceptual y Trazabilidad Matemática del Modelo Tarifario en Lenguaje Llano Institucional
A4: 1. LA ECUACIÓN FUNDAMENTAL DE LA TARIFA TÉCNICA (Tt = COV / IPK)
A5: ¿Qué significa en lenguaje llano? La Tarifa Técnica es el precio exacto por viaje que cubre todos los costos reales de operación (combustible, repuestos, chofer, seguros), la reposición periódica del microbús (depreciación) y una ganancia justa y normal al capital invertido (11% anual), sin generar ni pérdidas ni sobreganancias extraordinarias. Fórmula directa de equilibrio financiero: Tt = Costo Económico Regulatorio Mensual / Pasajeros Transportados al Mes Tt = Bs. 18.790,59 / 6.995,74 pasajeros = Bs. 2,6860 por viaje (Ponderada) -> Tarifa Adulto: Bs. 3,45 por viaje. Formulación equivalente por productividad: Tt = Costo por Kilómetro (CPK) / Índice de Pasajeros por Kilómetro (IPK) Tt = (Bs. 8,6489 / km) / (3,21999 pax / km) = Bs. 2,6860 por viaje. Esta equivalencia demuestra que si el microbús transporta más pasajeros por kilómetro (mayor IPK), la tarifa técnica necesaria baja.
A19: 2. DESCOMPOSICIÓN DE COSTOS DE OPERACIÓN VEHICULAR (COV: FIJOS VS. VARIABLES)
A20: ¿Cómo se calculan los costos? • Costos Variables (por km): Dependen exclusivamente de cuánto rueda el microbús. Si el vehículo no opera, el costo es cero. - Combustible: (km_mes / 5,50 km/l) * 17,95 Bs/l * 1,15 (ralentí) = Bs. 8.154,14/mes (Bs. 3,7532/km). - Mantenimiento variable: 25,14% de la planilla técnica v2 = Bs. 721,38/mes (Bs. 0,3320/km). • Costos Fijos (por tiempo): Se pagan mes a mes independientemente del kilometraje recorrido. - Mantenimiento fijo: 74,86% de la planilla técnica v2 = Bs. 2.148,37/mes. - Conductor: Salario Bs. 3.300 + provisión aguinaldo Bs. 274,99 = Bs. 3.574,99/mes. - Administrativos y seguros: SOAT, impuestos, ITV, sindicato, permisos y seguro a terceros = Bs. 720,42/mes. • Costo de Capital Regulatorio: - Depreciación lineal: (Bs. 198.360 valor reposición) / 120 meses = Bs. 1.653,00/mes. - Retorno justo al capital: Bs. 198.360 * 11% anual / 12 meses = Bs. 1.818,30/mes. Total Costo Regulatorio: Bs. 15.319,29 (OPEX en efectivo) + Bs. 3.471,30 (Capital) = Bs. 18.790,59/mes.
A35: 3. EL FACTOR DE CONCILIACIÓN DE OFERTA DE RED
A36: ¿Por qué existe y para qué se usa? Cuando multiplicamos la distancia de ciclo de las 32 rutas por su flota asignada y por 3 vueltas diarias, obtenemos 82.066 km/día. Sin embargo, el aforo satelital GPS independiente midió 82.475 km/día en la red real (una diferencia de +409 km/día, o +0,50%). Esta diferencia ocurre por desvíos de tráfico, posicionamiento de unidades y variaciones de ruta. Fórmula del factor de conciliación: Factor = km auditados en calle / km teóricos de las rutas = 82.475 / 82.066 = 1,004978 (1,0050). El modelo aplica este factor proporcionalmente a cada ruta, garantizando que la suma de costos de las 32 líneas coincida exactamente al centavo con el costo total auditado del sistema, sin sesgos a favor ni en contra de ningún sindicato.
A47: 4. SEPARACIÓN ESTRICTA: CUENTA DE CAJA REAL VS. CUENTA ECONÓMICA REGULATORIA
A48: ¿Por qué es fundamental para la transparencia con el GAM de Sucre? Históricamente, los transportistas confunden tres conceptos distintos: el salario por trabajar, la utilidad del capital y las deudas bancarias. El modelo profesional v3.2 separa rigurosamente las dos cuentas: 1. Cuenta Regulatoria: Determina la Tarifa Técnica. Incluye OPEX real + depreciación del microbús + 11% de ganancia sobre el vehículo. Las deudas bancarias particulares del transportista NO se cargan a la tarifa del usuario (sería cobrar dos veces el microbús). 2. Cuenta de Caja del Hogar: Muestra el dinero en efectivo que realmente llega a la familia del transportista. Con Tarifa Vigente (Bs. 4,50): El hogar recibe Bs. 3.575 (sueldo) + Bs. 1.818 (retorno) + Bs. 5.729 (utilidad excedente) = Bs. 11.122,76/mes. Con Tarifa Social (Bs. 3,80): El hogar recibe Bs. 3.575 (sueldo) + Bs. 1.818 (retorno) + Bs. 2.015 (excedente) = Bs. 7.408,02/mes. Con Tarifa Técnica (Bs. 3,45): El hogar recibe Bs. 3.575 (sueldo) + Bs. 1.818 (retorno normal) = Bs. 5.393,29/mes. En todos los casos, el transportista tiene garantizado un ingreso digno muy superior al salario mínimo nacional.
A60: 5. GLOSARIO DE TÉRMINOS TÉCNICOS
A61: • COV: Costo de Operación Vehicular. Suma integral de insumos, personal, impuestos y capital por microbús. • IPK: Índice de Pasajeros por Kilómetro. Mide la productividad de demanda (Pasajeros transportados divididos entre km recorridos). • CPK: Costo por Kilómetro. Gasto económico promedio que cuesta rodar un kilómetro en la red (Bs. 8,65/km). • CTP: Costo por Pasajero. Costo unitario promedio de trasladar un pasajero (equivale a la tarifa técnica ponderada = Bs. 2,69/viaje). • FO: Factor de Ocupación. Relación entre pasajeros a bordo y la capacidad nominal de asientos del microbús. • WTP: Disposición a Pagar (Willingness to Pay). Máximo precio que los usuarios están dispuestos a abonar según encuestas. • WACC: Costo Promedio Ponderado de Capital (11% anual). Tasa de retorno justa reconocida a la inversión en material rodante. • Fórmula Laspeyres: Índice ponderado de canasta de costos fija para revisar la tarifa trimestralmente ante inflación objetiva.
